Caught plotting error: Maximum buckets is 128
Traceback (most recent call last):
  File "/data-l/varvara/chia-blockchain/.venv/bin/chia", line 6, in <module>
    sys.exit(main())
  File "/data-l/varvara/chia-blockchain/chia/cmds/chia.py", line 139, in main
    cli()  # pylint: disable=no-value-for-parameter
  File "/data-l/varvara/chia-blockchain/.venv/lib/python3.10/site-packages/click/core.py", line 1157, in __call__
    return self.main(*args, **kwargs)
  File "/data-l/varvara/chia-blockchain/.venv/lib/python3.10/site-packages/click/core.py", line 1078, in main
    rv = self.invoke(ctx)
  File "/data-l/varvara/chia-blockchain/.venv/lib/python3.10/site-packages/click/core.py", line 1688, in invoke
    return _process_result(sub_ctx.command.invoke(sub_ctx))
  File "/data-l/varvara/chia-blockchain/.venv/lib/python3.10/site-packages/click/core.py", line 1434, in invoke
    return ctx.invoke(self.callback, **ctx.params)
  File "/data-l/varvara/chia-blockchain/.venv/lib/python3.10/site-packages/click/core.py", line 783, in invoke
    return __callback(*args, **kwargs)
  File "/data-l/varvara/chia-blockchain/.venv/lib/python3.10/site-packages/click/decorators.py", line 33, in new_func
    return f(get_current_context(), *args, **kwargs)
  File "/data-l/varvara/chia-blockchain/chia/cmds/plotters.py", line 17, in plotters_cmd
    call_plotters(ctx.obj["root_path"], args)
  File "/data-l/varvara/chia-blockchain/chia/plotters/plotters.py", line 541, in call_plotters
    plot_chia(args, chia_root_path)
  File "/data-l/varvara/chia-blockchain/chia/plotters/chiapos.py", line 58, in plot_chia
    asyncio.run(create_plots(params, plot_keys))
  File "/usr/lib/python3.10/asyncio/runners.py", line 44, in run
    return loop.run_until_complete(main)
  File "/usr/lib/python3.10/asyncio/base_events.py", line 649, in run_until_complete
    return future.result()
  File "/data-l/varvara/chia-blockchain/chia/plotting/create_plots.py", line 241, in create_plots
    plotter.create_plot_disk(
RuntimeError: std::exception
